=================================================================== test session starts ====================================================================
platform darwin -- Python 3.10.0b2, pytest-6.2.5, py-1.10.0, pluggy-1.0.0
rootdir: /Users/jwr003/coding/pytest-fold, configfile: pyproject.toml, testpaths: tests
plugins: session2file-0.1.11
collecting ... 
collected 18 items                                                                                                                                         

tests/test_pytest_fold.py .F.F.F.FFF...FF..E                                                                                                         [100%]

========================================================================== ERRORS ==========================================================================
_______________________________________________________ ERROR at setup of test_fixture_for_fun_fail ________________________________________________________
file /Users/jwr003/coding/pytest-fold/tests/test_pytest_fold.py, line 135
  def test_fixture_for_fun_fail(fixture_for_fun):
E       fixture 'fixture_for_fun' not found
>       available fixtures: cache, capfd, capfdbinary, caplog, capsys, capsysbinary, doctest_namespace, fold, monkeypatch, pytestconfig, record_property, record_testsuite_property, record_xml_attribute, recwarn, tmp_path, tmp_path_factory, tmpdir, tmpdir_factory
>       use 'pytest --fixtures [testpath]' for help on them.

/Users/jwr003/coding/pytest-fold/tests/test_pytest_fold.py:135
========================================================================= FAILURES =========================================================================
____________________________________________________________________ test_which_fails_1 ____________________________________________________________________
Traceback (most recent call last):
  File "/Users/jwr003/coding/pytest-fold/tests/test_pytest_fold.py", line 18, in test_which_fails_1
    assert 0
AssertionError: assert 0
____________________________________________________________________ test_which_fails_2 ____________________________________________________________________
Traceback (most recent call last):
  File "/Users/jwr003/coding/pytest-fold/tests/test_pytest_fold.py", line 26, in test_which_fails_2
    assert 0
AssertionError: assert 0
____________________________________________________________________ test_which_fails_3 ____________________________________________________________________
Traceback (most recent call last):
  File "/Users/jwr003/coding/pytest-fold/tests/test_pytest_fold.py", line 34, in test_which_fails_3
    assert 0
AssertionError: assert 0
_______________________________________________________________________ test_fail_1 ________________________________________________________________________
Traceback (most recent call last):
  File "/Users/jwr003/coding/pytest-fold/tests/test_pytest_fold.py", line 74, in test_fail_1
    assert False
AssertionError: assert False
_______________________________________________________________________ test_fail_2 ________________________________________________________________________
Traceback (most recent call last):
  File "/Users/jwr003/coding/pytest-fold/tests/test_pytest_fold.py", line 80, in test_fail_2
    assert False
AssertionError: assert False
_______________________________________________________________________ test_fail_3 ________________________________________________________________________
Traceback (most recent call last):
  File "/Users/jwr003/coding/pytest-fold/tests/test_pytest_fold.py", line 86, in test_fail_3
    assert False
AssertionError: assert False
____________________________________________________________ test_which_fails_and_has_stdout_1 _____________________________________________________________
Traceback (most recent call last):
  File "/Users/jwr003/coding/pytest-fold/tests/test_pytest_fold.py", line 109, in test_which_fails_and_has_stdout_1
    assert 0 == 1
AssertionError: assert 0 == 1
------------------------------------------------------------------- Captured stdout call -------------------------------------------------------------------
this test fails
_______________________________________________________ test_which_pauses_and_fails_and_has_stdout_1 _______________________________________________________
Traceback (most recent call last):
  File "/Users/jwr003/coding/pytest-fold/tests/test_pytest_fold.py", line 115, in test_which_pauses_and_fails_and_has_stdout_1
    assert 0 == -11
AssertionError: assert 0 == -11
------------------------------------------------------------------- Captured stdout call -------------------------------------------------------------------
this test pauses, then fails
================================================================= short test summary info ==================================================================
FAILED tests/test_pytest_fold.py::test_which_fails_1 - assert 0
FAILED tests/test_pytest_fold.py::test_which_fails_2 - assert 0
FAILED tests/test_pytest_fold.py::test_which_fails_3 - assert 0
FAILED tests/test_pytest_fold.py::test_fail_1 - assert False
FAILED tests/test_pytest_fold.py::test_fail_2 - assert False
FAILED tests/test_pytest_fold.py::test_fail_3 - assert False
FAILED tests/test_pytest_fold.py::test_which_fails_and_has_stdout_1 - assert 0 == 1
FAILED tests/test_pytest_fold.py::test_which_pauses_and_fails_and_has_stdout_1 - assert 0 == -11
ERROR tests/test_pytest_fold.py::test_fixture_for_fun_fail
=========================================================== [31m[1m8 failed[0m, [32m9 passed[0m, [31m[1m1 error[0m[31m in 2.39s[0m[31m ===========================================================
