=================================================================== test session starts ====================================================================
platform darwin -- Python 3.10.0b2, pytest-6.2.5, py-1.10.0, pluggy-1.0.0
rootdir: /Users/jwr003/coding/pytest-fold, configfile: pyproject.toml, testpaths: tests
plugins: session2file-0.1.11
collecting ... 
collected 18 items                                                                                                                                         

tests/test_pytest_fold.py .F
INTERNALERROR> Traceback (most recent call last):
INTERNALERROR>   File "/Users/jwr003/coding/pytest-fold/.venv/lib/python3.10/site-packages/_pytest/main.py", line 269, in wrap_session
INTERNALERROR>     session.exitstatus = doit(config, session) or 0
INTERNALERROR>   File "/Users/jwr003/coding/pytest-fold/.venv/lib/python3.10/site-packages/_pytest/main.py", line 323, in _main
INTERNALERROR>     config.hook.pytest_runtestloop(session=session)
INTERNALERROR>   File "/Users/jwr003/coding/pytest-fold/.venv/lib/python3.10/site-packages/pluggy/_hooks.py", line 265, in __call__
INTERNALERROR>     return self._hookexec(self.name, self.get_hookimpls(), kwargs, firstresult)
INTERNALERROR>   File "/Users/jwr003/coding/pytest-fold/.venv/lib/python3.10/site-packages/pluggy/_manager.py", line 80, in _hookexec
INTERNALERROR>     return self._inner_hookexec(hook_name, methods, kwargs, firstresult)
INTERNALERROR>   File "/Users/jwr003/coding/pytest-fold/.venv/lib/python3.10/site-packages/pluggy/_callers.py", line 60, in _multicall
INTERNALERROR>     return outcome.get_result()
INTERNALERROR>   File "/Users/jwr003/coding/pytest-fold/.venv/lib/python3.10/site-packages/pluggy/_result.py", line 60, in get_result
INTERNALERROR>     raise ex[1].with_traceback(ex[2])
INTERNALERROR>   File "/Users/jwr003/coding/pytest-fold/.venv/lib/python3.10/site-packages/pluggy/_callers.py", line 39, in _multicall
INTERNALERROR>     res = hook_impl.function(*args)
INTERNALERROR>   File "/Users/jwr003/coding/pytest-fold/.venv/lib/python3.10/site-packages/_pytest/main.py", line 348, in pytest_runtestloop
INTERNALERROR>     item.config.hook.pytest_runtest_protocol(item=item, nextitem=nextitem)
INTERNALERROR>   File "/Users/jwr003/coding/pytest-fold/.venv/lib/python3.10/site-packages/pluggy/_hooks.py", line 265, in __call__
INTERNALERROR>     return self._hookexec(self.name, self.get_hookimpls(), kwargs, firstresult)
INTERNALERROR>   File "/Users/jwr003/coding/pytest-fold/.venv/lib/python3.10/site-packages/pluggy/_manager.py", line 80, in _hookexec
INTERNALERROR>     return self._inner_hookexec(hook_name, methods, kwargs, firstresult)
INTERNALERROR>   File "/Users/jwr003/coding/pytest-fold/.venv/lib/python3.10/site-packages/pluggy/_callers.py", line 60, in _multicall
INTERNALERROR>     return outcome.get_result()
INTERNALERROR>   File "/Users/jwr003/coding/pytest-fold/.venv/lib/python3.10/site-packages/pluggy/_result.py", line 60, in get_result
INTERNALERROR>     raise ex[1].with_traceback(ex[2])
INTERNALERROR>   File "/Users/jwr003/coding/pytest-fold/.venv/lib/python3.10/site-packages/pluggy/_callers.py", line 39, in _multicall
INTERNALERROR>     res = hook_impl.function(*args)
INTERNALERROR>   File "/Users/jwr003/coding/pytest-fold/.venv/lib/python3.10/site-packages/_pytest/runner.py", line 109, in pytest_runtest_protocol
INTERNALERROR>     runtestprotocol(item, nextitem=nextitem)
INTERNALERROR>   File "/Users/jwr003/coding/pytest-fold/.venv/lib/python3.10/site-packages/_pytest/runner.py", line 126, in runtestprotocol
INTERNALERROR>     reports.append(call_and_report(item, "call", log))
INTERNALERROR>   File "/Users/jwr003/coding/pytest-fold/.venv/lib/python3.10/site-packages/_pytest/runner.py", line 219, in call_and_report
INTERNALERROR>     hook.pytest_runtest_logreport(report=report)
INTERNALERROR>   File "/Users/jwr003/coding/pytest-fold/.venv/lib/python3.10/site-packages/pluggy/_hooks.py", line 265, in __call__
INTERNALERROR>     return self._hookexec(self.name, self.get_hookimpls(), kwargs, firstresult)
INTERNALERROR>   File "/Users/jwr003/coding/pytest-fold/.venv/lib/python3.10/site-packages/pluggy/_manager.py", line 80, in _hookexec
INTERNALERROR>     return self._inner_hookexec(hook_name, methods, kwargs, firstresult)
INTERNALERROR>   File "/Users/jwr003/coding/pytest-fold/.venv/lib/python3.10/site-packages/pluggy/_callers.py", line 55, in _multicall
INTERNALERROR>     gen.send(outcome)
INTERNALERROR>   File "/Users/jwr003/coding/pytest-fold/conftest.py", line 39, in pytest_runtest_logreport
INTERNALERROR>     report.longrepr.chain[0][0].reprentries[0].lines.insert(0, "===MARKER1===")
INTERNALERROR> AttributeError: 'ReprExceptionInfo' object has no attribute 'chain'

=============================================================== [31m[1m1 failed[0m, [32m1 passed[0m[31m in 0.02s[0m[31m ================================================================
