==>PYTEST_FOLD_MARKER_SESSIONSTART_BEGIN<==
============================= test session starts ==============================
platform darwin -- Python 3.9.5, pytest-6.2.5, py-1.11.0, pluggy-1.0.0 -- /Users/jwr003/coding/pytest-fold/venv/bin/python
cachedir: .pytest_cache
rootdir: /Users/jwr003/coding/pytest-fold
plugins: fold-0.5.0
==>PYTEST_FOLD_MARKER_SESSIONSTART_END<==
collecting ... collected 18 items

tests/test_pytest_fold.py::test_version FAILED                           [  5%]
tests/test_pytest_fold.py::test_which_fails_1 FAILED                     [ 11%]
tests/test_pytest_fold.py::test_which_passes_1 PASSED                    [ 16%]
tests/test_pytest_fold.py::test_which_fails_2 FAILED                     [ 22%]
tests/test_pytest_fold.py::test_which_passes_2 PASSED                    [ 27%]
tests/test_pytest_fold.py::test_which_fails_3 FAILED                     [ 33%]
tests/test_pytest_fold.py::test_which_passes_3 PASSED                    [ 38%]
tests/test_pytest_fold.py::test_fail_1 FAILED                            [ 44%]
tests/test_pytest_fold.py::test_fail_2 FAILED                            [ 50%]
tests/test_pytest_fold.py::test_fail_3 FAILED                            [ 55%]
tests/test_pytest_fold.py::test_pass_1 PASSED                            [ 61%]
tests/test_pytest_fold.py::test_pass_2 PASSED                            [ 66%]
tests/test_pytest_fold.py::test_pass_3 PASSED                            [ 72%]
tests/test_pytest_fold.py::test_which_fails_and_has_stdout_1 FAILED      [ 77%]
tests/test_pytest_fold.py::test_which_pauses_and_fails_and_has_stdout_1 FAILED [ 83%]
tests/test_pytest_fold.py::test_which_passes_and_has_stdout_2 PASSED     [ 88%]
tests/test_pytest_fold.py::test_summary PASSED                           [ 94%]
tests/test_pytest_fold.py::test_fixture_for_fun_fail ERROR               [100%][?1049h[1;68r(B[m[4l[?7h[?1h=[39;49m[?1h=[?25l[?1000h

==>PYTEST_FOLD_MARKER_SESSIONFINISH_BEGIN<==
==>PYTEST_FOLD_MARKER_SESSIONFINISH_END<==


==================================== ERRORS ====================================
_________________ ERROR at setup of test_fixture_for_fun_fail __________________
file /Users/jwr003/coding/pytest-fold/tests/test_pytest_fold.py, line 135
  def test_fixture_for_fun_fail(fixture_for_fun):
E       fixture 'fixture_for_fun' not found
>       available fixtures: cache, capfd, capfdbinary, caplog, capsys, capsysbinary, doctest_namespace, fold, monkeypatch, pytestconfig, record_property, record_testsuite_property, record_xml_attribute, recwarn, tmp_path, tmp_path_factory, tmpdir, tmpdir_factory
>       use 'pytest --fixtures [testpath]' for help on them.

/Users/jwr003/coding/pytest-fold/tests/test_pytest_fold.py:135
=================================== FAILURES ===================================
_________________________________ test_version _________________________________

==>PYTEST_FOLD_MARKER_FAILURE_BEGIN<==
    def test_version():
>       assert __version__ == "0.1.0"
E       AssertionError: assert '0.5.0' == '0.1.0'
E         - 0.1.0
E         ?   ^
E         + 0.5.0
E         ?   ^

tests/test_pytest_fold.py:14: AssertionError
==>PYTEST_FOLD_MARKER_FAILURE_END<==
______________________________ test_which_fails_1 ______________________________

==>PYTEST_FOLD_MARKER_FAILURE_BEGIN<==
    def test_which_fails_1():
>       assert 0
E       assert 0

tests/test_pytest_fold.py:18: AssertionError
==>PYTEST_FOLD_MARKER_FAILURE_END<==
______________________________ test_which_fails_2 ______________________________

==>PYTEST_FOLD_MARKER_FAILURE_BEGIN<==
    def test_which_fails_2():
>       assert 0
E       assert 0

tests/test_pytest_fold.py:26: AssertionError
==>PYTEST_FOLD_MARKER_FAILURE_END<==
______________________________ test_which_fails_3 ______________________________

==>PYTEST_FOLD_MARKER_FAILURE_BEGIN<==
    def test_which_fails_3():
>       assert 0
E       assert 0

tests/test_pytest_fold.py:34: AssertionError
==>PYTEST_FOLD_MARKER_FAILURE_END<==
_________________________________ test_fail_1 __________________________________

==>PYTEST_FOLD_MARKER_FAILURE_BEGIN<==
    def test_fail_1():
        a = 0
        time.sleep(0.05)
>       assert False
E       assert False

tests/test_pytest_fold.py:74: AssertionError
==>PYTEST_FOLD_MARKER_FAILURE_END<==
_________________________________ test_fail_2 __________________________________

==>PYTEST_FOLD_MARKER_FAILURE_BEGIN<==
    def test_fail_2():
        a = 0
        time.sleep(0.05)
>       assert False
E       assert False

tests/test_pytest_fold.py:80: AssertionError
==>PYTEST_FOLD_MARKER_FAILURE_END<==
_________________________________ test_fail_3 __________________________________

==>PYTEST_FOLD_MARKER_FAILURE_BEGIN<==
    def test_fail_3():
        a = 0
        time.sleep(0.05)
>       assert False
E       assert False

tests/test_pytest_fold.py:86: AssertionError
==>PYTEST_FOLD_MARKER_FAILURE_END<==
______________________ test_which_fails_and_has_stdout_1 _______________________

capsys = <_pytest.capture.CaptureFixture object at 0x10bb409a0>

==>PYTEST_FOLD_MARKER_FAILURE_BEGIN<==
    def test_which_fails_and_has_stdout_1(capsys):
        print("this test fails")
>       assert 0 == 1
E       assert 0 == 1
E         +0
E         -1

tests/test_pytest_fold.py:109: AssertionError
==>PYTEST_FOLD_MARKER_FAILURE_END<==
----------------------------- Captured stdout call -----------------------------
this test fails
_________________ test_which_pauses_and_fails_and_has_stdout_1 _________________

capsys = <_pytest.capture.CaptureFixture object at 0x10bb59640>

==>PYTEST_FOLD_MARKER_FAILURE_BEGIN<==
    def test_which_pauses_and_fails_and_has_stdout_1(capsys):
        print("this test pauses, then fails")
        time.sleep(2)
>       assert 0 == -11
E       assert 0 == -11
E         +0
E         --11

tests/test_pytest_fold.py:115: AssertionError
==>PYTEST_FOLD_MARKER_FAILURE_END<==
----------------------------- Captured stdout call -----------------------------
this test pauses, then fails
=========================== short test summary info ============================
FAILED tests/test_pytest_fold.py::test_version - AssertionError: assert '0.5....
FAILED tests/test_pytest_fold.py::test_which_fails_1 - assert 0
FAILED tests/test_pytest_fold.py::test_which_fails_2 - assert 0
FAILED tests/test_pytest_fold.py::test_which_fails_3 - assert 0
FAILED tests/test_pytest_fold.py::test_fail_1 - assert False
FAILED tests/test_pytest_fold.py::test_fail_2 - assert False
FAILED tests/test_pytest_fold.py::test_fail_3 - assert False
FAILED tests/test_pytest_fold.py::test_which_fails_and_has_stdout_1 - assert ...
FAILED tests/test_pytest_fold.py::test_which_pauses_and_fails_and_has_stdout_1
ERROR tests/test_pytest_fold.py::test_fixture_for_fun_fail
===================== 9 failed, 8 passed, 1 error in 2.72s =====================
